Workbook

Sheet Paramètres
A1: PARAMÈTRES DE SIMULATION
A2: Cellules jaunes = à saisir | Vert = calculé automatiquement | Modifiez uniquement les jaunes
A4: BIEN IMMOBILIER
A5: Prix d'acquisition (€) | B5: 200000
A6: Quote-part terrain non amortissable (%) | B6: 0.15
A7: Frais de notaire (%) | B7: 0.08
A8: Travaux immobiliers (€) | B8: 5000
A9: Mobilier / équipements (€) | B9: 5000
A10: Apport personnel (€) | B10: 40000
A11: Progression valeur/an (%) | B11: 0.015
A12: Durée d'analyse (ans, max 20) | B12: 15
A14: CALCULS BIEN
A15: Valeur amortissable bien (€) | B15: =B5*(1-B6) -> 170000
A16: Frais notaire (€) | B16: =B5*B7 -> 16000
A17: Montant emprunté (€) | B17: =B5+B5*B7+B8-B10 -> 181000
A18: Valeur bien à l'échéance (€) | B18: =(B5+B8)*(1+B11)^B12 -> 256297.57
A20: CRÉDIT
A21: Taux crédit (%) | B21: 0.035
A22: Durée crédit (ans) | B22: 20
A23: Mensualité (€) | B23: =IFERROR(B17*(B21/12)/(1-(1+B21/12)^(-B22*12)),0) -> 1049.7271
A24: Annuité crédit (€) | B24: =B23*12 -> 12596.725
A26: REVENUS LOCATIFS
A27: Loyer mensuel HC (€) | B27: 800
A28: Croissance loyer/an (%) | B28: 0.015
A29: Taux de vacance (%) | B29: 0.083333333
A31: CHARGES ANNUELLES
A32: Entretien / réparations (€) | B32: 1200
A33: Taxe foncière (€) | B33: 900
A34: Assurance PNO (€) | B34: 150
A35: Frais comptable LMNP (€) | B35: 400
A36: CFE — LMNP uniquement (€) | B36: 200
A37: Croissance charges/an (%) | B37: 0.02
A39: AMORTISSEMENTS — LMNP RÉEL UNIQUEMENT
A40: Durée amort. bien (ans) | B40: 30
A41: Durée amort. travaux (ans) | B41: 12
A42: Durée amort. mobilier (ans) | B42: 7
A43: Amort. bien/an (€) | B43: =B15/B40 -> 5666.6667
A44: Amort. travaux/an (€) | B44: =B8/B41 -> 416.66667
A45: Amort. mobilier/an (€) | B45: =B9/B42 -> 714.28571
A46: Total amortissements/an (€) | B46: =B43+B44+B45 -> 6797.619
...

Sheet Amortissement crédit
A1: TABLEAU D'AMORTISSEMENT MENSUEL | H1: INTÉRÊTS PAR ANNÉE
H2: Capital restant/an →
A3: Mois | B3: An | C3: Capital début | D3: Intérêts | E3: Capital remb. | F3: Capital restant | H3: Année | I3: Intérêts annuels (€) | J3: Capital restant fin an
A4: 0 | C4: =Paramètres!B17 -> 181000 | F4: =Paramètres!B17 -> 181000 | H4: 1 | I4: =SUMIF(B5:B244,1,D5:D244) -> 6233.5685 | J4: =INDEX(F5:F244,1*12) -> 174636.84
A5: 1 | B5: 1 | C5: =F4 -> 181000 | D5: =IF(C5>0,C5*Paramètres!B21/12,0) -> 527.91667 | E5: =IF(C5>0,MIN(Paramètres!B23-D5,C5),0) -> 521.81042 | F5: =MAX(C5-E5,0) -> 180478.19 | H5: 2 | I5: =SUMIF(B5:B244,2,D5:D244) -> 6007.2504 | J5: =INDEX(F5:F244,2*12) -> 168047.37
A6: 2 | B6: 1 | C6: =F5 -> 180478.19 | D6: =IF(C6>0,C6*Paramètres!B21/12,0) -> 526.39472 | E6: =IF(C6>0,MIN(Paramètres!B23-D6,C6),0) -> 523.33237 | F6: =MAX(C6-E6,0) -> 179954.86 | H6: 3 | I6: =SUMIF(B5:B244,3,D5:D244) -> 5772.8828 | J6: =INDEX(F5:F244,3*12) -> 161223.53
A7: 3 | B7: 1 | C7: =F6 -> 179954.86 | D7: =IF(C7>0,C7*Paramètres!B21/12,0) -> 524.86833 | E7: =IF(C7>0,MIN(Paramètres!B23-D7,C7),0) -> 524.85876 | F7: =MAX(C7-E7,0) -> 179430 | H7: 4 | I7: =SUMIF(B5:B244,4,D5:D244) -> 5530.1796 | J7: =INDEX(F5:F244,4*12) -> 154156.98
A8: 4 | B8: 1 | C8: =F7 -> 179430 | D8: =IF(C8>0,C8*Paramètres!B21/12,0) -> 523.3375 | E8: =IF(C8>0,MIN(Paramètres!B23-D8,C8),0) -> 526.38959 | F8: =MAX(C8-E8,0) -> 178903.61 | H8: 5 | I8: =SUMIF(B5:B244,5,D5:D244) -> 5278.8441 | J8: =INDEX(F5:F244,5*12) -> 146839.1
A9: 5 | B9: 1 | C9: =F8 -> 178903.61 | D9: =IF(C9>0,C9*Paramètres!B21/12,0) -> 521.80219 | E9: =IF(C9>0,MIN(Paramètres!B23-D9,C9),0) -> 527.9249 | F9: =MAX(C9-E9,0) -> 178375.68 | H9: 6 | I9: =SUMIF(B5:B244,6,D5:D244) -> 5018.5693 | J9: =INDEX(F5:F244,6*12) -> 139260.94
A10: 6 | B10: 1 | C10: =F9 -> 178375.68 | D10: =IF(C10>0,C10*Paramètres!B21/12,0) -> 520.26241 | E10: =IF(C10>0,MIN(Paramètres!B23-D10,C10),0) -> 529.46468 | F10: =MAX(C10-E10,0) -> 177846.22 | H10: 7 | I10: =SUMIF(B5:B244,7,D5:D244) -> 4749.0374 | J10: =INDEX(F5:F244,7*12) -> 131413.26
A11: 7 | B11: 1 | C11: =F10 -> 177846.22 | D11: =IF(C11>0,C11*Paramètres!B21/12,0) -> 518.71814 | E11: =IF(C11>0,MIN(Paramètres!B23-D11,C11),0) -> 531.00895 | F11: =MAX(C11-E11,0) -> 177315.21 | H11: 8 | I11: =SUMIF(B5:B244,8,D5:D244) -> 4469.9191 | J11: =INDEX(F5:F244,8*12) -> 123286.45
A12: 8 | B12: 1 | C12: =F11 -> 177315.21 | D12: =IF(C12>0,C12*Paramètres!B21/12,0) -> 517.16936 | E12: =IF(C12>0,MIN(Paramètres!B23-D12,C12),0) -> 532.55773 | F12: =MAX(C12-E12,0) -> 176782.65 | H12: 9 | I12: =SUMIF(B5:B244,9,D5:D244) -> 4180.8734 | J12: =INDEX(F5:F244,9*12) -> 114870.6
A13: 9 | B13: 1 | C13: =F12 -> 176782.65 | D13: =IF(C13>0,C13*Paramètres!B21/12,0) -> 515.61607 | E13: =IF(C13>0,MIN(Paramètres!B23-D13,C13),0) -> 534.11102 | F13: =MAX(C13-E13,0) -> 176248.54 | H13: 10 | I13: =SUMIF(B5:B244,10,D5:D244) -> 3881.5472 | J13: =INDEX(F5:F244,10*12) -> 106155.42
A14: 10 | B14: 1 | C14: =F13 -> 176248.54 | D14: =IF(C14>0,C14*Paramètres!B21/12,0) -> 514.05825 | E14: =IF(C14>0,MIN(Paramètres!B23-D14,C14),0) -> 535.66884 | F14: =MAX(C14-E14,0) -> 175712.87 | H14: 11 | I14: =SUMIF(B5:B244,11,D5:D244) -> 3571.5749 | J14: =INDEX(F5:F244,11*12) -> 97130.271
A15: 11 | B15: 1 | C15: =F14 -> 175712.87 | D15: =IF(C15>0,C15*Paramètres!B21/12,0) -> 512.49588 | E15: =IF(C15>0,MIN(Paramètres!B23-D15,C15),0) -> 537.23121 | F15: =MAX(C15-E15,0) -> 175175.64 | H15: 12 | I15: =SUMIF(B5:B244,12,D5:D244) -> 3250.5778 | J15: =INDEX(F5:F244,12*12) -> 87784.124
A16: 12 | B16: 1 | C16: =F15 -> 175175.64 | D16: =IF(C16>0,C16*Paramètres!B21/12,0) -> 510.92895 | E16: =IF(C16>0,MIN(Paramètres!B23-D16,C16),0) -> 538.79814 | F16: =MAX(C16-E16,0) -> 174636.84 | H16: 13 | I16: =SUMIF(B5:B244,13,D5:D244) -> 2918.1638 | J16: =INDEX(F5:F244,13*12) -> 78105.562
A17: 13 | B17: 2 | C17: =F16 -> 174636.84 | D17: =IF(C17>0,C17*Paramètres!B21/12,0) -> 509.35746 | E17: =IF(C17>0,MIN(Paramètres!B23-D17,C17),0) -> 540.36963 | F17: =MAX(C17-E17,0) -> 174096.47 | H17: 14 | I17: =SUMIF(B5:B244,14,D5:D244) -> 2573.9268 | J17: =INDEX(F5:F244,14*12) -> 68082.764
A18: 14 | B18: 2 | C18: =F17 -> 174096.47 | D18: =IF(C18>0,C18*Paramètres!B21/12,0) -> 507.78138 | E18: =IF(C18>0,MIN(Paramètres!B23-D18,C18),0) -> 541.94571 | F18: =MAX(C18-E18,0) -> 173554.53 | H18: 15 | I18: =SUMIF(B5:B244,15,D5:D244) -> 2217.4465 | J18: =INDEX(F5:F244,15*12) -> 57703.485
A19: 15 | B19: 2 | C19: =F18 -> 173554.53 | D19: =IF(C19>0,C19*Paramètres!B21/12,0) -> 506.20071 | E19: =IF(C19>0,MIN(Paramètres!B23-D19,C19),0) -> 543.52638 | F19: =MAX(C19-E19,0) -> 173011 | H19: 16 | I19: =SUMIF(B5:B244,16,D5:D244) -> 1848.2871 | J19: =INDEX(F5:F244,16*12) -> 46955.047
A20: 16 | B20: 2 | C20: =F19 -> 173011 | D20: =IF(C20>0,C20*Paramètres!B21/12,0) -> 504.61542 | E20: =IF(C20>0,MIN(Paramètres!B23-D20,C20),0) -> 545.11167 | F20: =MAX(C20-E20,0) -> 172465.89 | H20: 17 | I20: =SUMIF(B5:B244,17,D5:D244) -> 1465.998 | J20: =INDEX(F5:F244,17*12) -> 35824.32
A21: 17 | B21: 2 | C21: =F20 -> 172465.89 | D21: =IF(C21>0,C21*Paramètres!B21/12,0) -> 503.02551 | E21: =IF(C21>0,MIN(Paramètres!B23-D21,C21),0) -> 546.70158 | F21: =MAX(C21-E21,0) -> 171919.19 | H21: 18 | I21: =SUMIF(B5:B244,18,D5:D244) -> 1070.1119 | J21: =INDEX(F5:F244,18*12) -> 24297.707
A22: 18 | B22: 2 | C22: =F21 -> 171919.19 | D22: =IF(C22>0,C22*Paramètres!B21/12,0) -> 501.43097 | E22: =IF(C22>0,MIN(Paramètres!B23-D22,C22),0) -> 548.29612 | F22: =MAX(C22-E22,0) -> 171370.89 | H22: 19 | I22: =SUMIF(B5:B244,19,D5:D244) -> 660.14539 | J22: =INDEX(F5:F244,19*12) -> 12361.127
A23: 19 | B23: 2 | C23: =F22 -> 171370.89 | D23: =IF(C23>0,C23*Paramètres!B21/12,0) -> 499.83177 | E23: =IF(C23>0,MIN(Paramètres!B23-D23,C23),0) -> 549.89532 | F23: =MAX(C23-E23,0) -> 170821 | H23: 20 | I23: =SUMIF(B5:B244,20,D5:D244) -> 235.59763 | J23: =INDEX(F5:F244,20*12) -> 1.0504664e-09
A24: 20 | B24: 2 | C24: =F23 -> 170821 | D24: =IF(C24>0,C24*Paramètres!B21/12,0) -> 498.22791 | E24: =IF(C24>0,MIN(Paramètres!B23-D24,C24),0) -> 551.49918 | F24: =MAX(C24-E24,0) -> 170269.5
A25: 21 | B25: 2 | C25: =F24 -> 170269.5 | D25: =IF(C25>0,C25*Paramètres!B21/12,0) -> 496.61937 | E25: =IF(C25>0,MIN(Paramètres!B23-D25,C25),0) -> 553.10772 | F25: =MAX(C25-E25,0) -> 169716.39
A26: 22 | B26: 2 | C26: =F25 -> 169716.39 | D26: =IF(C26>0,C26*Paramètres!B21/12,0) -> 495.00614 | E26: =IF(C26>0,MIN(Paramètres!B23-D26,C26),0) -> 554.72095 | F26: =MAX(C26-E26,0) -> 169161.67
A27: 23 | B27: 2 | C27: =F26 -> 169161.67 | D27: =IF(C27>0,C27*Paramètres!B21/12,0) -> 493.3882 | E27: =IF(C27>0,MIN(Paramètres!B23-D27,C27),0) -> 556.33889 | F27: =MAX(C27-E27,0) -> 168605.33
A28: 24 | B28: 2 | C28: =F27 -> 168605.33 | D28: =IF(C28>0,C28*Paramètres!B21/12,0) -> 491.76555 | E28: =IF(C28>0,MIN(Paramètres!B23-D28,C28),0) -> 557.96154 | F28: =MAX(C28-E28,0) -> 168047.37
A29: 25 | B29: 3 | C29: =F28 -> 168047.37 | D29: =IF(C29>0,C29*Paramètres!B21/12,0) -> 490.13816 | E29: =IF(C29>0,MIN(Paramètres!B23-D29,C29),0) -> 559.58893 | F29: =MAX(C29-E29,0) -> 167487.78
A30: 26 | B30: 3 | C30: =F29 -> 167487.78 | D30: =IF(C30>0,C30*Paramètres!B21/12,0) -> 488.50602 | E30: =IF(C30>0,MIN(Paramètres!B23-D30,C30),0) -> 561.22107 | F30: =MAX(C30-E30,0) -> 166926.56
A31: 27 | B31: 3 | C31: =F30 -> 166926.56 | D31: =IF(C31>0,C31*Paramètres!B21/12,0) -> 486.86913 | E31: =IF(C31>0,MIN(Paramètres!B23-D31,C31),0) -> 562.85796 | F31: =MAX(C31-E31,0) -> 166363.7
A32: 28 | B32: 3 | C32: =F31 -> 166363.7 | D32: =IF(C32>0,C32*Paramètres!B21/12,0) -> 485.22746 | E32: =IF(C32>0,MIN(Paramètres!B23-D32,C32),0) -> 564.49963 | F32: =MAX(C32-E32,0) -> 165799.2
A33: 29 | B33: 3 | C33: =F32 -> 165799.2 | D33: =IF(C33>0,C33*Paramètres!B21/12,0) -> 483.581 | E33: =IF(C33>0,MIN(Paramètres!B23-D33,C33),0) -> 566.14609 | F33: =MAX(C33-E33,0) -> 165233.06
A34: 30 | B34: 3 | C34: =F33 -> 165233.06 | D34: =IF(C34>0,C34*Paramètres!B21/12,0) -> 481.92974 | E34: =IF(C34>0,MIN(Paramètres!B23-D34,C34),0) -> 567.79735 | F34: =MAX(C34-E34,0) -> 164665.26
A35: 31 | B35: 3 | C35: =F34 -> 164665.26 | D35: =IF(C35>0,C35*Paramètres!B21/12,0) -> 480.27367 | E35: =IF(C35>0,MIN(Paramètres!B23-D35,C35),0) -> 569.45342 | F35: =MAX(C35-E35,0) -> 164095.8
A36: 32 | B36: 3 | C36: =F35 -> 164095.8 | D36: =IF(C36>0,C36*Paramètres!B21/12,0) -> 478.61276 | E36: =IF(C36>0,MIN(Paramètres!B23-D36,C36),0) -> 571.11433 | F36: =MAX(C36-E36,0) -> 163524.69
A37: 33 | B37: 3 | C37: =F36 -> 163524.69 | D37: =IF(C37>0,C37*Paramètres!B21/12,0) -> 476.94701 | E37: =IF(C37>0,MIN(Paramètres!B23-D37,C37),0) -> 572.78008 | F37: =MAX(C37-E37,0) -> 162951.91
A38: 34 | B38: 3 | C38: =F37 -> 162951.91 | D38: =IF(C38>0,C38*Paramètres!B21/12,0) -> 475.2764 | E38: =IF(C38>0,MIN(Paramètres!B23-D38,C38),0) -> 574.45069 | F38: =MAX(C38-E38,0) -> 162377.46
A39: 35 | B39: 3 | C39: =F38 -> 162377.46 | D39: =IF(C39>0,C39*Paramètres!B21/12,0) -> 473.60092 | E39: =IF(C39>0,MIN(Paramètres!B23-D39,C39),0) -> 576.12617 | F39: =MAX(C39-E39,0) -> 161801.33
A40: 36 | B40: 3 | C40: =F39 -> 161801.33 | D40: =IF(C40>0,C40*Paramètres!B21/12,0) -> 471.92055 | E40: =IF(C40>0,MIN(Paramètres!B23-D40,C40),0) -> 577.80653 | F40: =MAX(C40-E40,0) -> 161223.53
...

Sheet Location nue
A1: LOCATION NUE — DÉTAIL ANNUEL
A3: An | B3: Loyer brut | C3: Vacance | D3: Loyer net | E3: Charges déd. | F3: Intérêts | G3: Rev. imposable | H3: Impôt | I3: Cash-flow | J3: Flux TRI | K3: Stock déficit début | L3: Stock déficit fin | M3: Résultat avant report | N3: Déficit total | O3: Dont intérêts (non imputable global) | P3: Dont autres charges | Q3: Imputé sur revenu global | R3: Nouveau report
A4: 0 | J4: =-Paramètres!B10 -> -40000
A5: 1 | B5: =Paramètres!B27*12*(1+Paramètres!B28)^(1-1) -> 9600 | C5: =B5*Paramètres!B29 -> 800 | D5: =B5-C5 -> 8800 | E5: =(Paramètres!B32+Paramètres!B33+Paramètres!B34)*(1+Paramètres!B37)^(1-1) -> 2250 | F5: ='Amortissement crédit'!I4 -> 6233.5685 | G5: =IF(M5<0,0,MAX(M5-K5,0)) -> 316.43153 | H5: =IF(M5<0,-Q5*Paramètres!$B$50,G5*(Paramètres!$B$50+Paramètres!$B$51)) -> 149.35568 | I5: =D5-E5-H5-Paramètres!$B$24 -> -6196.0808 | J5: =I5+IF(1=Paramètres!B12,Paramètres!B18-'Amortissement crédit'!J4-Paramètres!$B$75,0) -> -6196.0808 | K5: =0 -> 0 | L5: =IF(M5<0,K5+R5,MAX(K5-M5,0)) -> 0 | M5: =D5-E5-F5 -> 316.43153 | N5: =IF(M5<0,-M5,0) -> 0 | O5: =IF(M5<0,MAX(F5-D5,0),0) -> 0 | P5: =N5-O5 -> 0 | Q5: =IF(M5<0,MIN(P5,Paramètres!$B$81)*Paramètres!$B$82,0) -> 0 | R5: =IF(M5<0,N5-Q5,0) -> 0
A6: 2 | B6: =Paramètres!B27*12*(1+Paramètres!B28)^(2-1) -> 9744 | C6: =B6*Paramètres!B29 -> 812 | D6: =B6-C6 -> 8932 | E6: =(Paramètres!B32+Paramètres!B33+Paramètres!B34)*(1+Paramètres!B37)^(2-1) -> 2295 | F6: ='Amortissement crédit'!I5 -> 6007.2504 | G6: =IF(M6<0,0,MAX(M6-K6,0)) -> 629.74962 | H6: =IF(M6<0,-Q6*Paramètres!$B$50,G6*(Paramètres!$B$50+Paramètres!$B$51)) -> 297.24182 | I6: =D6-E6-H6-Paramètres!$B$24 -> -6256.9669 | J6: =I6+IF(2=Paramètres!B12,Paramètres!B18-'Amortissement crédit'!J5-Paramètres!$B$75,0) -> -6256.9669 | K6: =L5 -> 0 | L6: =IF(M6<0,K6+R6,MAX(K6-M6,0)) -> 0 | M6: =D6-E6-F6 -> 629.74962 | N6: =IF(M6<0,-M6,0) -> 0 | O6: =IF(M6<0,MAX(F6-D6,0),0) -> 0 | P6: =N6-O6 -> 0 | Q6: =IF(M6<0,MIN(P6,Paramètres!$B$81)*Paramètres!$B$82,0) -> 0 | R6: =IF(M6<0,N6-Q6,0) -> 0
A7: 3 | B7: =Paramètres!B27*12*(1+Paramètres!B28)^(3-1) -> 9890.16 | C7: =B7*Paramètres!B29 -> 824.18 | D7: =B7-C7 -> 9065.98 | E7: =(Paramètres!B32+Paramètres!B33+Paramètres!B34)*(1+Paramètres!B37)^(3-1) -> 2340.9 | F7: ='Amortissement crédit'!I6 -> 5772.8828 | G7: =IF(M7<0,0,MAX(M7-K7,0)) -> 952.19716 | H7: =IF(M7<0,-Q7*Paramètres!$B$50,G7*(Paramètres!$B$50+Paramètres!$B$51)) -> 449.43706 | I7: =D7-E7-H7-Paramètres!$B$24 -> -6321.0821 | J7: =I7+IF(3=Paramètres!B12,Paramètres!B18-'Amortissement crédit'!J6-Paramètres!$B$75,0) -> -6321.0821 | K7: =L6 -> 0 | L7: =IF(M7<0,K7+R7,MAX(K7-M7,0)) -> 0 | M7: =D7-E7-F7 -> 952.19716 | N7: =IF(M7<0,-M7,0) -> 0 | O7: =IF(M7<0,MAX(F7-D7,0),0) -> 0 | P7: =N7-O7 -> 0 | Q7: =IF(M7<0,MIN(P7,Paramètres!$B$81)*Paramètres!$B$82,0) -> 0 | R7: =IF(M7<0,N7-Q7,0) -> 0
A8: 4 | B8: =Paramètres!B27*12*(1+Paramètres!B28)^(4-1) -> 10038.512 | C8: =B8*Paramètres!B29 -> 836.5427 | D8: =B8-C8 -> 9201.9697 | E8: =(Paramètres!B32+Paramètres!B33+Paramètres!B34)*(1+Paramètres!B37)^(4-1) -> 2387.718 | F8: ='Amortissement crédit'!I7 -> 5530.1796 | G8: =IF(M8<0,0,MAX(M8-K8,0)) -> 1284.0721 | H8: =IF(M8<0,-Q8*Paramètres!$B$50,G8*(Paramètres!$B$50+Paramètres!$B$51)) -> 606.08205 | I8: =D8-E8-H8-Paramètres!$B$24 -> -6388.5554 | J8: =I8+IF(4=Paramètres!B12,Paramètres!B18-'Amortissement crédit'!J7-Paramètres!$B$75,0) -> -6388.5554 | K8: =L7 -> 0 | L8: =IF(M8<0,K8+R8,MAX(K8-M8,0)) -> 0 | M8: =D8-E8-F8 -> 1284.0721 | N8: =IF(M8<0,-M8,0) -> 0 | O8: =IF(M8<0,MAX(F8-D8,0),0) -> 0 | P8: =N8-O8 -> 0 | Q8: =IF(M8<0,MIN(P8,Paramètres!$B$81)*Paramètres!$B$82,0) -> 0 | R8: =IF(M8<0,N8-Q8,0) -> 0
A9: 5 | B9: =Paramètres!B27*12*(1+Paramètres!B28)^(5-1) -> 10189.09 | C9: =B9*Paramètres!B29 -> 849.09084 | D9: =B9-C9 -> 9339.9992 | E9: =(Paramètres!B32+Paramètres!B33+Paramètres!B34)*(1+Paramètres!B37)^(5-1) -> 2435.4724 | F9: ='Amortissement crédit'!I8 -> 5278.8441 | G9: =IF(M9<0,0,MAX(M9-K9,0)) -> 1625.6828 | H9: =IF(M9<0,-Q9*Paramètres!$B$50,G9*(Paramètres!$B$50+Paramètres!$B$51)) -> 767.32229 | I9: =D9-E9-H9-Paramètres!$B$24 -> -6459.5205 | J9: =I9+IF(5=Paramètres!B12,Paramètres!B18-'Amortissement crédit'!J8-Paramètres!$B$75,0) -> -6459.5205 | K9: =L8 -> 0 | L9: =IF(M9<0,K9+R9,MAX(K9-M9,0)) -> 0 | M9: =D9-E9-F9 -> 1625.6828 | N9: =IF(M9<0,-M9,0) -> 0 | O9: =IF(M9<0,MAX(F9-D9,0),0) -> 0 | P9: =N9-O9 -> 0 | Q9: =IF(M9<0,MIN(P9,Paramètres!$B$81)*Paramètres!$B$82,0) -> 0 | R9: =IF(M9<0,N9-Q9,0) -> 0
A10: 6 | B10: =Paramètres!B27*12*(1+Paramètres!B28)^(6-1) -> 10341.926 | C10: =B10*Paramètres!B29 -> 861.8272 | D10: =B10-C10 -> 9480.0992 | E10: =(Paramètres!B32+Paramètres!B33+Paramètres!B34)*(1+Paramètres!B37)^(6-1) -> 2484.1818 | F10: ='Amortissement crédit'!I9 -> 5018.5693 | G10: =IF(M10<0,0,MAX(M10-K10,0)) -> 1977.3481 | H10: =IF(M10<0,-Q10*Paramètres!$B$50,G10*(Paramètres!$B$50+Paramètres!$B$51)) -> 933.30829 | I10: =D10-E10-H10-Paramètres!$B$24 -> -6534.1159 | J10: =I10+IF(6=Paramètres!B12,Paramètres!B18-'Amortissement crédit'!J9-Paramètres!$B$75,0) -> -6534.1159 | K10: =L9 -> 0 | L10: =IF(M10<0,K10+R10,MAX(K10-M10,0)) -> 0 | M10: =D10-E10-F10 -> 1977.3481 | N10: =IF(M10<0,-M10,0) -> 0 | O10: =IF(M10<0,MAX(F10-D10,0),0) -> 0 | P10: =N10-O10 -> 0 | Q10: =IF(M10<0,MIN(P10,Paramètres!$B$81)*Paramètres!$B$82,0) -> 0 | R10: =IF(M10<0,N10-Q10,0) -> 0
A11: 7 | B11: =Paramètres!B27*12*(1+Paramètres!B28)^(7-1) -> 10497.055 | C11: =B11*Paramètres!B29 -> 874.75461 | D11: =B11-C11 -> 9622.3007 | E11: =(Paramètres!B32+Paramètres!B33+Paramètres!B34)*(1+Paramètres!B37)^(7-1) -> 2533.8654 | F11: ='Amortissement crédit'!I10 -> 4749.0374 | G11: =IF(M11<0,0,MAX(M11-K11,0)) -> 2339.3978 | H11: =IF(M11<0,-Q11*Paramètres!$B$50,G11*(Paramètres!$B$50+Paramètres!$B$51)) -> 1104.1958 | I11: =D11-E11-H11-Paramètres!$B$24 -> -6612.4856 | J11: =I11+IF(7=Paramètres!B12,Paramètres!B18-'Amortissement crédit'!J10-Paramètres!$B$75,0) -> -6612.4856 | K11: =L10 -> 0 | L11: =IF(M11<0,K11+R11,MAX(K11-M11,0)) -> 0 | M11: =D11-E11-F11 -> 2339.3978 | N11: =IF(M11<0,-M11,0) -> 0 | O11: =IF(M11<0,MAX(F11-D11,0),0) -> 0 | P11: =N11-O11 -> 0 | Q11: =IF(M11<0,MIN(P11,Paramètres!$B$81)*Paramètres!$B$82,0) -> 0 | R11: =IF(M11<0,N11-Q11,0) -> 0
A12: 8 | B12: =Paramètres!B27*12*(1+Paramètres!B28)^(8-1) -> 10654.511 | C12: =B12*Paramètres!B29 -> 887.87593 | D12: =B12-C12 -> 9766.6352 | E12: =(Paramètres!B32+Paramètres!B33+Paramètres!B34)*(1+Paramètres!B37)^(8-1) -> 2584.5428 | F12: ='Amortissement crédit'!I11 -> 4469.9191 | G12: =IF(M12<0,0,MAX(M12-K12,0)) -> 2712.1734 | H12: =IF(M12<0,-Q12*Paramètres!$B$50,G12*(Paramètres!$B$50+Paramètres!$B$51)) -> 1280.1458 | I12: =D12-E12-H12-Paramètres!$B$24 -> -6694.7784 | J12: =I12+IF(8=Paramètres!B12,Paramètres!B18-'Amortissement crédit'!J11-Paramètres!$B$75,0) -> -6694.7784 | K12: =L11 -> 0 | L12: =IF(M12<0,K12+R12,MAX(K12-M12,0)) -> 0 | M12: =D12-E12-F12 -> 2712.1734 | N12: =IF(M12<0,-M12,0) -> 0 | O12: =IF(M12<0,MAX(F12-D12,0),0) -> 0 | P12: =N12-O12 -> 0 | Q12: =IF(M12<0,MIN(P12,Paramètres!$B$81)*Paramètres!$B$82,0) -> 0 | R12: =IF(M12<0,N12-Q12,0) -> 0
A13: 9 | B13: =Paramètres!B27*12*(1+Paramètres!B28)^(9-1) -> 10814.329 | C13: =B13*Paramètres!B29 -> 901.19407 | D13: =B13-C13 -> 9913.1348 | E13: =(Paramètres!B32+Paramètres!B33+Paramètres!B34)*(1+Paramètres!B37)^(9-1) -> 2636.2336 | F13: ='Amortissement crédit'!I12 -> 4180.8734 | G13: =IF(M13<0,0,MAX(M13-K13,0)) -> 3096.0278 | H13: =IF(M13<0,-Q13*Paramètres!$B$50,G13*(Paramètres!$B$50+Paramètres!$B$51)) -> 1461.3251 | I13: =D13-E13-H13-Paramètres!$B$24 -> -6781.149 | J13: =I13+IF(9=Paramètres!B12,Paramètres!B18-'Amortissement crédit'!J12-Paramètres!$B$75,0) -> -6781.149 | K13: =L12 -> 0 | L13: =IF(M13<0,K13+R13,MAX(K13-M13,0)) -> 0 | M13: =D13-E13-F13 -> 3096.0278 | N13: =IF(M13<0,-M13,0) -> 0 | O13: =IF(M13<0,MAX(F13-D13,0),0) -> 0 | P13: =N13-O13 -> 0 | Q13: =IF(M13<0,MIN(P13,Paramètres!$B$81)*Paramètres!$B$82,0) -> 0 | R13: =IF(M13<0,N13-Q13,0) -> 0
A14: 10 | B14: =Paramètres!B27*12*(1+Paramètres!B28)^(10-1) -> 10976.544 | C14: =B14*Paramètres!B29 -> 914.71198 | D14: =B14-C14 -> 10061.832 | E14: =(Paramètres!B32+Paramètres!B33+Paramètres!B34)*(1+Paramètres!B37)^(10-1) -> 2688.9583 | F14: ='Amortissement crédit'!I13 -> 3881.5472 | G14: =IF(M14<0,0,MAX(M14-K14,0)) -> 3491.3263 | H14: =IF(M14<0,-Q14*Paramètres!$B$50,G14*(Paramètres!$B$50+Paramètres!$B$51)) -> 1647.906 | I14: =D14-E14-H14-Paramètres!$B$24 -> -6871.7576 | J14: =I14+IF(10=Paramètres!B12,Paramètres!B18-'Amortissement crédit'!J13-Paramètres!$B$75,0) -> -6871.7576 | K14: =L13 -> 0 | L14: =IF(M14<0,K14+R14,MAX(K14-M14,0)) -> 0 | M14: =D14-E14-F14 -> 3491.3263 | N14: =IF(M14<0,-M14,0) -> 0 | O14: =IF(M14<0,MAX(F14-D14,0),0) -> 0 | P14: =N14-O14 -> 0 | Q14: =IF(M14<0,MIN(P14,Paramètres!$B$81)*Paramètres!$B$82,0) -> 0 | R14: =IF(M14<0,N14-Q14,0) -> 0
A15: 11 | B15: =Paramètres!B27*12*(1+Paramètres!B28)^(11-1) -> 11141.192 | C15: =B15*Paramètres!B29 -> 928.43266 | D15: =B15-C15 -> 10212.759 | E15: =(Paramètres!B32+Paramètres!B33+Paramètres!B34)*(1+Paramètres!B37)^(11-1) -> 2742.7374 | F15: ='Amortissement crédit'!I14 -> 3571.5749 | G15: =IF(M15<0,0,MAX(M15-K15,0)) -> 3898.447 | H15: =IF(M15<0,-Q15*Paramètres!$B$50,G15*(Paramètres!$B$50+Paramètres!$B$51)) -> 1840.067 | I15: =D15-E15-H15-Paramètres!$B$24 -> -6966.7702 | J15: =I15+IF(11=Paramètres!B12,Paramètres!B18-'Amortissement crédit'!J14-Paramètres!$B$75,0) -> -6966.7702 | K15: =L14 -> 0 | L15: =IF(M15<0,K15+R15,MAX(K15-M15,0)) -> 0 | M15: =D15-E15-F15 -> 3898.447 | N15: =IF(M15<0,-M15,0) -> 0 | O15: =IF(M15<0,MAX(F15-D15,0),0) -> 0 | P15: =N15-O15 -> 0 | Q15: =IF(M15<0,MIN(P15,Paramètres!$B$81)*Paramètres!$B$82,0) -> 0 | R15: =IF(M15<0,N15-Q15,0) -> 0
A16: 12 | B16: =Paramètres!B27*12*(1+Paramètres!B28)^(12-1) -> 11308.31 | C16: =B16*Paramètres!B29 -> 942.35915 | D16: =B16-C16 -> 10365.951 | E16: =(Paramètres!B32+Paramètres!B33+Paramètres!B34)*(1+Paramètres!B37)^(12-1) -> 2797.5922 | F16: ='Amortissement crédit'!I15 -> 3250.5778 | G16: =IF(M16<0,0,MAX(M16-K16,0)) -> 4317.7807 | H16: =IF(M16<0,-Q16*Paramètres!$B$50,G16*(Paramètres!$B$50+Paramètres!$B$51)) -> 2037.9925 | I16: =D16-E16-H16-Paramètres!$B$24 -> -7066.3591 | J16: =I16+IF(12=Paramètres!B12,Paramètres!B18-'Amortissement crédit'!J15-Paramètres!$B$75,0) -> -7066.3591 | K16: =L15 -> 0 | L16: =IF(M16<0,K16+R16,MAX(K16-M16,0)) -> 0 | M16: =D16-E16-F16 -> 4317.7807 | N16: =IF(M16<0,-M16,0) -> 0 | O16: =IF(M16<0,MAX(F16-D16,0),0) -> 0 | P16: =N16-O16 -> 0 | Q16: =IF(M16<0,MIN(P16,Paramètres!$B$81)*Paramètres!$B$82,0) -> 0 | R16: =IF(M16<0,N16-Q16,0) -> 0
A17: 13 | B17: =Paramètres!B27*12*(1+Paramètres!B28)^(13-1) -> 11477.934 | C17: =B17*Paramètres!B29 -> 956.49454 | D17: =B17-C17 -> 10521.44 | E17: =(Paramètres!B32+Paramètres!B33+Paramètres!B34)*(1+Paramètres!B37)^(13-1) -> 2853.544 | F17: ='Amortissement crédit'!I16 -> 2918.1638 | G17: =IF(M17<0,0,MAX(M17-K17,0)) -> 4749.7321 | H17: =IF(M17<0,-Q17*Paramètres!$B$50,G17*(Paramètres!$B$50+Paramètres!$B$51)) -> 2241.8735 | I17: =D17-E17-H17-Paramètres!$B$24 -> -7170.7028 | J17: =I17+IF(13=Paramètres!B12,Paramètres!B18-'Amortissement crédit'!J16-Paramètres!$B$75,0) -> -7170.7028 | K17: =L16 -> 0 | L17: =IF(M17<0,K17+R17,MAX(K17-M17,0)) -> 0 | M17: =D17-E17-F17 -> 4749.7321 | N17: =IF(M17<0,-M17,0) -> 0 | O17: =IF(M17<0,MAX(F17-D17,0),0) -> 0 | P17: =N17-O17 -> 0 | Q17: =IF(M17<0,MIN(P17,Paramètres!$B$81)*Paramètres!$B$82,0) -> 0 | R17: =IF(M17<0,N17-Q17,0) -> 0
A18: 14 | B18: =Paramètres!B27*12*(1+Paramètres!B28)^(14-1) -> 11650.103 | C18: =B18*Paramètres!B29 -> 970.84196 | D18: =B18-C18 -> 10679.262 | E18: =(Paramètres!B32+Paramètres!B33+Paramètres!B34)*(1+Paramètres!B37)^(14-1) -> 2910.6149 | F18: ='Amortissement crédit'!I17 -> 2573.9268 | G18: =IF(M18<0,0,MAX(M18-K18,0)) -> 5194.7197 | H18: =IF(M18<0,-Q18*Paramètres!$B$50,G18*(Paramètres!$B$50+Paramètres!$B$51)) -> 2451.9077 | I18: =D18-E18-H18-Paramètres!$B$24 -> -7279.9862 | J18: =I18+IF(14=Paramètres!B12,Paramètres!B18-'Amortissement crédit'!J17-Paramètres!$B$75,0) -> -7279.9862 | K18: =L17 -> 0 | L18: =IF(M18<0,K18+R18,MAX(K18-M18,0)) -> 0 | M18: =D18-E18-F18 -> 5194.7197 | N18: =IF(M18<0,-M18,0) -> 0 | O18: =IF(M18<0,MAX(F18-D18,0),0) -> 0 | P18: =N18-O18 -> 0 | Q18: =IF(M18<0,MIN(P18,Paramètres!$B$81)*Paramètres!$B$82,0) -> 0 | R18: =IF(M18<0,N18-Q18,0) -> 0
A19: 15 | B19: =Paramètres!B27*12*(1+Paramètres!B28)^(15-1) -> 11824.855 | C19: =B19*Paramètres!B29 -> 985.40458 | D19: =B19-C19 -> 10839.45 | E19: =(Paramètres!B32+Paramètres!B33+Paramètres!B34)*(1+Paramètres!B37)^(15-1) -> 2968.8272 | F19: ='Amortissement crédit'!I18 -> 2217.4465 | G19: =IF(M19<0,0,MAX(M19-K19,0)) -> 5653.1768 | H19: =IF(M19<0,-Q19*Paramètres!$B$50,G19*(Paramètres!$B$50+Paramètres!$B$51)) -> 2668.2994 | I19: =D19-E19-H19-Paramètres!$B$24 -> -7394.4013 | J19: =I19+IF(15=Paramètres!B12,Paramètres!B18-'Amortissement crédit'!J18-Paramètres!$B$75,0) -> 188938.13 | K19: =L18 -> 0 | L19: =IF(M19<0,K19+R19,MAX(K19-M19,0)) -> 0 | M19: =D19-E19-F19 -> 5653.1768 | N19: =IF(M19<0,-M19,0) -> 0 | O19: =IF(M19<0,MAX(F19-D19,0),0) -> 0 | P19: =N19-O19 -> 0 | Q19: =IF(M19<0,MIN(P19,Paramètres!$B$81)*Paramètres!$B$82,0) -> 0 | R19: =IF(M19<0,N19-Q19,0) -> 0
A20: 16 | B20: =Paramètres!B27*12*(1+Paramètres!B28)^(16-1) -> 12002.228 | C20: =B20*Paramètres!B29 -> 1000.1857 | D20: =B20-C20 -> 11002.042 | E20: =(Paramètres!B32+Paramètres!B33+Paramètres!B34)*(1+Paramètres!B37)^(16-1) -> 3028.2038 | F20: ='Amortissement crédit'!I19 -> 1848.2871 | G20: =IF(M20<0,0,MAX(M20-K20,0)) -> 6125.5513 | H20: =IF(M20<0,-Q20*Paramètres!$B$50,G20*(Paramètres!$B$50+Paramètres!$B$51)) -> 2891.2602 | I20: =D20-E20-H20-Paramètres!$B$24 -> -7514.1469 | J20: =I20+IF(16=Paramètres!B12,Paramètres!B18-'Amortissement crédit'!J19-Paramètres!$B$75,0) -> -7514.1469 | K20: =L19 -> 0 | L20: =IF(M20<0,K20+R20,MAX(K20-M20,0)) -> 0 | M20: =D20-E20-F20 -> 6125.5513 | N20: =IF(M20<0,-M20,0) -> 0 | O20: =IF(M20<0,MAX(F20-D20,0),0) -> 0 | P20: =N20-O20 -> 0 | Q20: =IF(M20<0,MIN(P20,Paramètres!$B$81)*Paramètres!$B$82,0) -> 0 | R20: =IF(M20<0,N20-Q20,0) -> 0
A21: 17 | B21: =Paramètres!B27*12*(1+Paramètres!B28)^(17-1) -> 12182.261 | C21: =B21*Paramètres!B29 -> 1015.1884 | D21: =B21-C21 -> 11167.073 | E21: =(Paramètres!B32+Paramètres!B33+Paramètres!B34)*(1+Paramètres!B37)^(17-1) -> 3088.7678 | F21: ='Amortissement crédit'!I20 -> 1465.998 | G21: =IF(M21<0,0,MAX(M21-K21,0)) -> 6612.307 | H21: =IF(M21<0,-Q21*Paramètres!$B$50,G21*(Paramètres!$B$50+Paramètres!$B$51)) -> 3121.0089 | I21: =D21-E21-H21-Paramètres!$B$24 -> -7639.429 | J21: =I21+IF(17=Paramètres!B12,Paramètres!B18-'Amortissement crédit'!J20-Paramètres!$B$75,0) -> -7639.429 | K21: =L20 -> 0 | L21: =IF(M21<0,K21+R21,MAX(K21-M21,0)) -> 0 | M21: =D21-E21-F21 -> 6612.307 | N21: =IF(M21<0,-M21,0) -> 0 | O21: =IF(M21<0,MAX(F21-D21,0),0) -> 0 | P21: =N21-O21 -> 0 | Q21: =IF(M21<0,MIN(P21,Paramètres!$B$81)*Paramètres!$B$82,0) -> 0 | R21: =IF(M21<0,N21-Q21,0) -> 0
A22: 18 | B22: =Paramètres!B27*12*(1+Paramètres!B28)^(18-1) -> 12364.995 | C22: =B22*Paramètres!B29 -> 1030.4163 | D22: =B22-C22 -> 11334.579 | E22: =(Paramètres!B32+Paramètres!B33+Paramètres!B34)*(1+Paramètres!B37)^(18-1) -> 3150.5432 | F22: ='Amortissement crédit'!I21 -> 1070.1119 | G22: =IF(M22<0,0,MAX(M22-K22,0)) -> 7113.9238 | H22: =IF(M22<0,-Q22*Paramètres!$B$50,G22*(Paramètres!$B$50+Paramètres!$B$51)) -> 3357.772 | I22: =D22-E22-H22-Paramètres!$B$24 -> -7770.4614 | J22: =I22+IF(18=Paramètres!B12,Paramètres!B18-'Amortissement crédit'!J21-Paramètres!$B$75,0) -> -7770.4614 | K22: =L21 -> 0 | L22: =IF(M22<0,K22+R22,MAX(K22-M22,0)) -> 0 | M22: =D22-E22-F22 -> 7113.9238 | N22: =IF(M22<0,-M22,0) -> 0 | O22: =IF(M22<0,MAX(F22-D22,0),0) -> 0 | P22: =N22-O22 -> 0 | Q22: =IF(M22<0,MIN(P22,Paramètres!$B$81)*Paramètres!$B$82,0) -> 0 | R22: =IF(M22<0,N22-Q22,0) -> 0
A23: 19 | B23: =Paramètres!B27*12*(1+Paramètres!B28)^(19-1) -> 12550.47 | C23: =B23*Paramètres!B29 -> 1045.8725 | D23: =B23-C23 -> 11504.598 | E23: =(Paramètres!B32+Paramètres!B33+Paramètres!B34)*(1+Paramètres!B37)^(19-1) -> 3213.5541 | F23: ='Amortissement crédit'!I22 -> 660.14539 | G23: =IF(M23<0,0,MAX(M23-K23,0)) -> 7630.8981 | H23: =IF(M23<0,-Q23*Paramètres!$B$50,G23*(Paramètres!$B$50+Paramètres!$B$51)) -> 3601.7839 | I23: =D23-E23-H23-Paramètres!$B$24 -> -7907.4655 | J23: =I23+IF(19=Paramètres!B12,Paramètres!B18-'Amortissement crédit'!J22-Paramètres!$B$75,0) -> -7907.4655 | K23: =L22 -> 0 | L23: =IF(M23<0,K23+R23,MAX(K23-M23,0)) -> 0 | M23: =D23-E23-F23 -> 7630.8981 | N23: =IF(M23<0,-M23,0) -> 0 | O23: =IF(M23<0,MAX(F23-D23,0),0) -> 0 | P23: =N23-O23 -> 0 | Q23: =IF(M23<0,MIN(P23,Paramètres!$B$81)*Paramètres!$B$82,0) -> 0 | R23: =IF(M23<0,N23-Q23,0) -> 0
A24: 20 | B24: =Paramètres!B27*12*(1+Paramètres!B28)^(20-1) -> 12738.727 | C24: =B24*Paramètres!B29 -> 1061.5606 | D24: =B24-C24 -> 11677.167 | E24: =(Paramètres!B32+Paramètres!B33+Paramètres!B34)*(1+Paramètres!B37)^(20-1) -> 3277.8251 | F24: ='Amortissement crédit'!I23 -> 235.59763 | G24: =IF(M24<0,0,MAX(M24-K24,0)) -> 8163.7438 | H24: =IF(M24<0,-Q24*Paramètres!$B$50,G24*(Paramètres!$B$50+Paramètres!$B$51)) -> 3853.2871 | I24: =D24-E24-H24-Paramètres!$B$24 -> -8050.6707 | J24: =I24+IF(20=Paramètres!B12,Paramètres!B18-'Amortissement crédit'!J23-Paramètres!$B$75,0) -> -8050.6707 | K24: =L23 -> 0 | L24: =IF(M24<0,K24+R24,MAX(K24-M24,0)) -> 0 | M24: =D24-E24-F24 -> 8163.7438 | N24: =IF(M24<0,-M24,0) -> 0 | O24: =IF(M24<0,MAX(F24-D24,0),0) -> 0 | P24: =N24-O24 -> 0 | Q24: =IF(M24<0,MIN(P24,Paramètres!$B$81)*Paramètres!$B$82,0) -> 0 | R24: =IF(M24<0,N24-Q24,0) -> 0
A26: RÉSUMÉ & RENDEMENTS
A27: Cash-flow cumulé hors revente (mise comprise) (€) | J27: =-Paramètres!B10+SUMPRODUCT((I5:I24)*(ROW(I5:I24)-4<=Paramètres!B12*1)) -> -140994.71
A28: Impôt cumulé sur loyers (€) | J28: =SUMPRODUCT((H5:H24)*(ROW(H5:H24)-4<=Paramètres!B12*1)) -> 19936.46
A29: Valeur du bien à l'échéance (€) | J29: =Paramètres!B18 -> 256297.57
A30: Capital restant dû à l'échéance (€) | J30: =INDEX('Amortissement crédit'!J4:J23,Paramètres!B12) -> 57703.485
A31: Patrimoine net estimé (€) | J31: =-Paramètres!B10+SUMPRODUCT((I5:I24)*(ROW(I5:I24)-4<=Paramètres!B12*1))+Paramètres!B18-INDEX('Amortissement crédit'!J4:J23,Paramètres!B12)-Paramètres!$B$75 -> 55337.823
A32: ★ TRI annuel (%) | J32: =IFERROR(IRR(INDEX($J$4:$J$24,1):INDEX($J$4:$J$24,Paramètres!$B$12+1)),"N/A") -> 0.035235007
A34: Multiple sur mise (x) | J34: =IFERROR((-Paramètres!B10+SUMPRODUCT((I5:I24)*(ROW(I5:I24)-4<=Paramètres!B12*1))+Paramètres!B18-INDEX('Amortissement crédit'!J4:J23,Paramètres!B12)-Paramètres!$B$75+Paramètres!B10)/(Paramètres!B10),"N/A") -> 2.3834456
A35: ★ Valeur future placement alternatif (€) | J35: =Paramètres!B56 -> 95862.328
A36: ★ Écart vs placement alternatif (€) | J36: =(-Paramètres!B10+SUMPRODUCT((I5:I24)*(ROW(I5:I24)-4<=Paramètres!B12*1))+Paramètres!B18-INDEX('Amortissement crédit'!J4:J23,Paramètres!B12)+Paramètres!B10)-Paramètres!B56 -> 1737.0488
A37: Charges déductibles location nue : entretien + taxe foncière + assurance PNO + intérêts d'emprunt. PAS de CFE, PAS de frais comptable, PAS d'amortissement du bien.

Sheet LMNP Micro-BIC
A1: LMNP MICRO-BIC — DÉTAIL ANNUEL
A3: An | B3: Loyer brut | C3: Vacance | D3: Loyer net | E3: Charges réelles | F3: Rev. imp. (50%) | G3: Impôt | H3: Cash-flow | I3: Flux TRI
A4: 0 | I4: =-Paramètres!B10 -> -40000
A5: 1 | B5: =Paramètres!B27*12*(1+Paramètres!B28)^(1-1) -> 9600 | C5: =B5*Paramètres!B29 -> 800 | D5: =B5-C5 -> 8800 | E5: =(Paramètres!$B$32+Paramètres!$B$33+Paramètres!$B$34)*(1+Paramètres!$B$37)^(1-1)+Paramètres!$B$36*(1+Paramètres!$B$78)^(1-1) -> 2450 | F5: =D5*0.5 -> 4400 | G5: =F5*(Paramètres!C50+Paramètres!C51) -> 2138.4 | H5: =D5-E5-G5-Paramètres!B24 -> -8385.1251 | I5: =H5+IF(1=Paramètres!B12,Paramètres!B18-'Amortissement crédit'!J4-Paramètres!$B$75,0) -> -8385.1251
A6: 2 | B6: =Paramètres!B27*12*(1+Paramètres!B28)^(2-1) -> 9744 | C6: =B6*Paramètres!B29 -> 812 | D6: =B6-C6 -> 8932 | E6: =(Paramètres!$B$32+Paramètres!$B$33+Paramètres!$B$34)*(1+Paramètres!$B$37)^(2-1)+Paramètres!$B$36*(1+Paramètres!$B$78)^(2-1) -> 2499 | F6: =D6*0.5 -> 4466 | G6: =F6*(Paramètres!C50+Paramètres!C51) -> 2170.476 | H6: =D6-E6-G6-Paramètres!B24 -> -8334.2011 | I6: =H6+IF(2=Paramètres!B12,Paramètres!B18-'Amortissement crédit'!J5-Paramètres!$B$75,0) -> -8334.2011
A7: 3 | B7: =Paramètres!B27*12*(1+Paramètres!B28)^(3-1) -> 9890.16 | C7: =B7*Paramètres!B29 -> 824.18 | D7: =B7-C7 -> 9065.98 | E7: =(Paramètres!$B$32+Paramètres!$B$33+Paramètres!$B$34)*(1+Paramètres!$B$37)^(3-1)+Paramètres!$B$36*(1+Paramètres!$B$78)^(3-1) -> 2548.98 | F7: =D7*0.5 -> 4532.99 | G7: =F7*(Paramètres!C50+Paramètres!C51) -> 2203.0331 | H7: =D7-E7-G7-Paramètres!B24 -> -8282.7582 | I7: =H7+IF(3=Paramètres!B12,Paramètres!B18-'Amortissement crédit'!J6-Paramètres!$B$75,0) -> -8282.7582
A8: 4 | B8: =Paramètres!B27*12*(1+Paramètres!B28)^(4-1) -> 10038.512 | C8: =B8*Paramètres!B29 -> 836.5427 | D8: =B8-C8 -> 9201.9697 | E8: =(Paramètres!$B$32+Paramètres!$B$33+Paramètres!$B$34)*(1+Paramètres!$B$37)^(4-1)+Paramètres!$B$36*(1+Paramètres!$B$78)^(4-1) -> 2599.9596 | F8: =D8*0.5 -> 4600.9848 | G8: =F8*(Paramètres!C50+Paramètres!C51) -> 2236.0786 | H8: =D8-E8-G8-Paramètres!B24 -> -8230.7936 | I8: =H8+IF(4=Paramètres!B12,Paramètres!B18-'Amortissement crédit'!J7-Paramètres!$B$75,0) -> -8230.7936
A9: 5 | B9: =Paramètres!B27*12*(1+Paramètres!B28)^(5-1) -> 10189.09 | C9: =B9*Paramètres!B29 -> 849.09084 | D9: =B9-C9 -> 9339.9992 | E9: =(Paramètres!$B$32+Paramètres!$B$33+Paramètres!$B$34)*(1+Paramètres!$B$37)^(5-1)+Paramètres!$B$36*(1+Paramètres!$B$78)^(5-1) -> 2651.9588 | F9: =D9*0.5 -> 4669.9996 | G9: =F9*(Paramètres!C50+Paramètres!C51) -> 2269.6198 | H9: =D9-E9-G9-Paramètres!B24 -> -8178.3044 | I9: =H9+IF(5=Paramètres!B12,Paramètres!B18-'Amortissement crédit'!J8-Paramètres!$B$75,0) -> -8178.3044
A10: 6 | B10: =Paramètres!B27*12*(1+Paramètres!B28)^(6-1) -> 10341.926 | C10: =B10*Paramètres!B29 -> 861.8272 | D10: =B10-C10 -> 9480.0992 | E10: =(Paramètres!$B$32+Paramètres!$B$33+Paramètres!$B$34)*(1+Paramètres!$B$37)^(6-1)+Paramètres!$B$36*(1+Paramètres!$B$78)^(6-1) -> 2704.998 | F10: =D10*0.5 -> 4740.0496 | G10: =F10*(Paramètres!C50+Paramètres!C51) -> 2303.6641 | H10: =D10-E10-G10-Paramètres!B24 -> -8125.2879 | I10: =H10+IF(6=Paramètres!B12,Paramètres!B18-'Amortissement crédit'!J9-Paramètres!$B$75,0) -> -8125.2879
A11: 7 | B11: =Paramètres!B27*12*(1+Paramètres!B28)^(7-1) -> 10497.055 | C11: =B11*Paramètres!B29 -> 874.75461 | D11: =B11-C11 -> 9622.3007 | E11: =(Paramètres!$B$32+Paramètres!$B$33+Paramètres!$B$34)*(1+Paramètres!$B$37)^(7-1)+Paramètres!$B$36*(1+Paramètres!$B$78)^(7-1) -> 2759.0979 | F11: =D11*0.5 -> 4811.1504 | G11: =F11*(Paramètres!C50+Paramètres!C51) -> 2338.2191 | H11: =D11-E11-G11-Paramètres!B24 -> -8071.7414 | I11: =H11+IF(7=Paramètres!B12,Paramètres!B18-'Amortissement crédit'!J10-Paramètres!$B$75,0) -> -8071.7414
A12: 8 | B12: =Paramètres!B27*12*(1+Paramètres!B28)^(8-1) -> 10654.511 | C12: =B12*Paramètres!B29 -> 887.87593 | D12: =B12-C12 -> 9766.6352 | E12: =(Paramètres!$B$32+Paramètres!$B$33+Paramètres!$B$34)*(1+Paramètres!$B$37)^(8-1)+Paramètres!$B$36*(1+Paramètres!$B$78)^(8-1) -> 2814.2799 | F12: =D12*0.5 -> 4883.3176 | G12: =F12*(Paramètres!C50+Paramètres!C51) -> 2373.2924 | H12: =D12-E12-G12-Paramètres!B24 -> -8017.6621 | I12: =H12+IF(8=Paramètres!B12,Paramètres!B18-'Amortissement crédit'!J11-Paramètres!$B$75,0) -> -8017.6621
A13: 9 | B13: =Paramètres!B27*12*(1+Paramètres!B28)^(9-1) -> 10814.329 | C13: =B13*Paramètres!B29 -> 901.19407 | D13: =B13-C13 -> 9913.1348 | E13: =(Paramètres!$B$32+Paramètres!$B$33+Paramètres!$B$34)*(1+Paramètres!$B$37)^(9-1)+Paramètres!$B$36*(1+Paramètres!$B$78)^(9-1) -> 2870.5655 | F13: =D13*0.5 -> 4956.5674 | G13: =F13*(Paramètres!C50+Paramètres!C51) -> 2408.8917 | H13: =D13-E13-G13-Paramètres!B24 -> -7963.0475 | I13: =H13+IF(9=Paramètres!B12,Paramètres!B18-'Amortissement crédit'!J12-Paramètres!$B$75,0) -> -7963.0475
A14: 10 | B14: =Paramètres!B27*12*(1+Paramètres!B28)^(10-1) -> 10976.544 | C14: =B14*Paramètres!B29 -> 914.71198 | D14: =B14-C14 -> 10061.832 | E14: =(Paramètres!$B$32+Paramètres!$B$33+Paramètres!$B$34)*(1+Paramètres!$B$37)^(10-1)+Paramètres!$B$36*(1+Paramètres!$B$78)^(10-1) -> 2927.9768 | F14: =D14*0.5 -> 5030.9159 | G14: =F14*(Paramètres!C50+Paramètres!C51) -> 2445.0251 | H14: =D14-E14-G14-Paramètres!B24 -> -7907.8952 | I14: =H14+IF(10=Paramètres!B12,Paramètres!B18-'Amortissement crédit'!J13-Paramètres!$B$75,0) -> -7907.8952
A15: 11 | B15: =Paramètres!B27*12*(1+Paramètres!B28)^(11-1) -> 11141.192 | C15: =B15*Paramètres!B29 -> 928.43266 | D15: =B15-C15 -> 10212.759 | E15: =(Paramètres!$B$32+Paramètres!$B$33+Paramètres!$B$34)*(1+Paramètres!$B$37)^(11-1)+Paramètres!$B$36*(1+Paramètres!$B$78)^(11-1) -> 2986.5363 | F15: =D15*0.5 -> 5106.3796 | G15: =F15*(Paramètres!C50+Paramètres!C51) -> 2481.7005 | H15: =D15-E15-G15-Paramètres!B24 -> -7852.2026 | I15: =H15+IF(11=Paramètres!B12,Paramètres!B18-'Amortissement crédit'!J14-Paramètres!$B$75,0) -> -7852.2026
A16: 12 | B16: =Paramètres!B27*12*(1+Paramètres!B28)^(12-1) -> 11308.31 | C16: =B16*Paramètres!B29 -> 942.35915 | D16: =B16-C16 -> 10365.951 | E16: =(Paramètres!$B$32+Paramètres!$B$33+Paramètres!$B$34)*(1+Paramètres!$B$37)^(12-1)+Paramètres!$B$36*(1+Paramètres!$B$78)^(12-1) -> 3046.2671 | F16: =D16*0.5 -> 5182.9753 | G16: =F16*(Paramètres!C50+Paramètres!C51) -> 2518.926 | H16: =D16-E16-G16-Paramètres!B24 -> -7795.9675 | I16: =H16+IF(12=Paramètres!B12,Paramètres!B18-'Amortissement crédit'!J15-Paramètres!$B$75,0) -> -7795.9675
A17: 13 | B17: =Paramètres!B27*12*(1+Paramètres!B28)^(13-1) -> 11477.934 | C17: =B17*Paramètres!B29 -> 956.49454 | D17: =B17-C17 -> 10521.44 | E17: =(Paramètres!$B$32+Paramètres!$B$33+Paramètres!$B$34)*(1+Paramètres!$B$37)^(13-1)+Paramètres!$B$36*(1+Paramètres!$B$78)^(13-1) -> 3107.1924 | F17: =D17*0.5 -> 5260.72 | G17: =F17*(Paramètres!C50+Paramètres!C51) -> 2556.7099 | H17: =D17-E17-G17-Paramètres!B24 -> -7739.1875 | I17: =H17+IF(13=Paramètres!B12,Paramètres!B18-'Amortissement crédit'!J16-Paramètres!$B$75,0) -> -7739.1875
A18: 14 | B18: =Paramètres!B27*12*(1+Paramètres!B28)^(14-1) -> 11650.103 | C18: =B18*Paramètres!B29 -> 970.84196 | D18: =B18-C18 -> 10679.262 | E18: =(Paramètres!$B$32+Paramètres!$B$33+Paramètres!$B$34)*(1+Paramètres!$B$37)^(14-1)+Paramètres!$B$36*(1+Paramètres!$B$78)^(14-1) -> 3169.3362 | F18: =D18*0.5 -> 5339.6308 | G18: =F18*(Paramètres!C50+Paramètres!C51) -> 2595.0605 | H18: =D18-E18-G18-Paramètres!B24 -> -7681.8604 | I18: =H18+IF(14=Paramètres!B12,Paramètres!B18-'Amortissement crédit'!J17-Paramètres!$B$75,0) -> -7681.8604
A19: 15 | B19: =Paramètres!B27*12*(1+Paramètres!B28)^(15-1) -> 11824.855 | C19: =B19*Paramètres!B29 -> 985.40458 | D19: =B19-C19 -> 10839.45 | E19: =(Paramètres!$B$32+Paramètres!$B$33+Paramètres!$B$34)*(1+Paramètres!$B$37)^(15-1)+Paramètres!$B$36*(1+Paramètres!$B$78)^(15-1) -> 3232.723 | F19: =D19*0.5 -> 5419.7252 | G19: =F19*(Paramètres!C50+Paramètres!C51) -> 2633.9865 | H19: =D19-E19-G19-Paramètres!B24 -> -7623.9841 | I19: =H19+IF(15=Paramètres!B12,Paramètres!B18-'Amortissement crédit'!J18-Paramètres!$B$75,0) -> 188708.55
A20: 16 | B20: =Paramètres!B27*12*(1+Paramètres!B28)^(16-1) -> 12002.228 | C20: =B20*Paramètres!B29 -> 1000.1857 | D20: =B20-C20 -> 11002.042 | E20: =(Paramètres!$B$32+Paramètres!$B$33+Paramètres!$B$34)*(1+Paramètres!$B$37)^(16-1)+Paramètres!$B$36*(1+Paramètres!$B$78)^(16-1) -> 3297.3774 | F20: =D20*0.5 -> 5501.0211 | G20: =F20*(Paramètres!C50+Paramètres!C51) -> 2673.4963 | H20: =D20-E20-G20-Paramètres!B24 -> -7565.5566 | I20: =H20+IF(16=Paramètres!B12,Paramètres!B18-'Amortissement crédit'!J19-Paramètres!$B$75,0) -> -7565.5566
A21: 17 | B21: =Paramètres!B27*12*(1+Paramètres!B28)^(17-1) -> 12182.261 | C21: =B21*Paramètres!B29 -> 1015.1884 | D21: =B21-C21 -> 11167.073 | E21: =(Paramètres!$B$32+Paramètres!$B$33+Paramètres!$B$34)*(1+Paramètres!$B$37)^(17-1)+Paramètres!$B$36*(1+Paramètres!$B$78)^(17-1) -> 3363.325 | F21: =D21*0.5 -> 5583.5364 | G21: =F21*(Paramètres!C50+Paramètres!C51) -> 2713.5987 | H21: =D21-E21-G21-Paramètres!B24 -> -7506.5759 | I21: =H21+IF(17=Paramètres!B12,Paramètres!B18-'Amortissement crédit'!J20-Paramètres!$B$75,0) -> -7506.5759
A22: 18 | B22: =Paramètres!B27*12*(1+Paramètres!B28)^(18-1) -> 12364.995 | C22: =B22*Paramètres!B29 -> 1030.4163 | D22: =B22-C22 -> 11334.579 | E22: =(Paramètres!$B$32+Paramètres!$B$33+Paramètres!$B$34)*(1+Paramètres!$B$37)^(18-1)+Paramètres!$B$36*(1+Paramètres!$B$78)^(18-1) -> 3430.5915 | F22: =D22*0.5 -> 5667.2895 | G22: =F22*(Paramètres!C50+Paramètres!C51) -> 2754.3027 | H22: =D22-E22-G22-Paramètres!B24 -> -7447.0403 | I22: =H22+IF(18=Paramètres!B12,Paramètres!B18-'Amortissement crédit'!J21-Paramètres!$B$75,0) -> -7447.0403
A23: 19 | B23: =Paramètres!B27*12*(1+Paramètres!B28)^(19-1) -> 12550.47 | C23: =B23*Paramètres!B29 -> 1045.8725 | D23: =B23-C23 -> 11504.598 | E23: =(Paramètres!$B$32+Paramètres!$B$33+Paramètres!$B$34)*(1+Paramètres!$B$37)^(19-1)+Paramètres!$B$36*(1+Paramètres!$B$78)^(19-1) -> 3499.2033 | F23: =D23*0.5 -> 5752.2988 | G23: =F23*(Paramètres!C50+Paramètres!C51) -> 2795.6172 | H23: =D23-E23-G23-Paramètres!B24 -> -7386.948 | I23: =H23+IF(19=Paramètres!B12,Paramètres!B18-'Amortissement crédit'!J22-Paramètres!$B$75,0) -> -7386.948
A24: 20 | B24: =Paramètres!B27*12*(1+Paramètres!B28)^(20-1) -> 12738.727 | C24: =B24*Paramètres!B29 -> 1061.5606 | D24: =B24-C24 -> 11677.167 | E24: =(Paramètres!$B$32+Paramètres!$B$33+Paramètres!$B$34)*(1+Paramètres!$B$37)^(20-1)+Paramètres!$B$36*(1+Paramètres!$B$78)^(20-1) -> 3569.1874 | F24: =D24*0.5 -> 5838.5833 | G24: =F24*(Paramètres!C50+Paramètres!C51) -> 2837.5515 | H24: =D24-E24-G24-Paramètres!B24 -> -7326.2974 | I24: =H24+IF(20=Paramètres!B12,Paramètres!B18-'Amortissement crédit'!J23-Paramètres!$B$75,0) -> -7326.2974
A26: RÉSUMÉ & RENDEMENTS
A27: Cash-flow cumulé hors revente (mise comprise) (€) | I27: =-Paramètres!B10+SUMPRODUCT((H5:H24)*(ROW(H5:H24)-4<=Paramètres!B12*1)) -> -160190.02
A28: Impôt cumulé sur loyers (€) | I28: =SUMPRODUCT((G5:G24)*(ROW(G5:G24)-4<=Paramètres!B12*1)) -> 35673.083
A29: Valeur du bien à l'échéance (€) | I29: =Paramètres!B18 -> 256297.57
A30: Capital restant dû à l'échéance (€) | I30: =INDEX('Amortissement crédit'!J4:J23,Paramètres!B12) -> 57703.485
A31: Patrimoine net estimé (€) | I31: =-Paramètres!B10+SUMPRODUCT((H5:H24)*(ROW(H5:H24)-4<=Paramètres!B12*1))+Paramètres!B18-INDEX('Amortissement crédit'!J4:J23,Paramètres!B12)-Paramètres!$B$75 -> 36142.517
A32: ★ TRI annuel (%) | I32: =IFERROR(IRR(INDEX($I$4:$I$24,1):INDEX($I$4:$I$24,Paramètres!$B$12+1)),"N/A") -> 0.021956762
A34: Multiple sur mise (x) | I34: =IFERROR((-Paramètres!B10+SUMPRODUCT((H5:H24)*(ROW(H5:H24)-4<=Paramètres!B12*1))+Paramètres!B18-INDEX('Amortissement crédit'!J4:J23,Paramètres!B12)-Paramètres!$B$75+Paramètres!B10)/(Paramètres!B10),"N/A") -> 1.9035629
A35: ★ Valeur future placement alternatif (€) | I35: =Paramètres!B56 -> 95862.328
A36: Micro-BIC : abattement forfaitaire 50% sur loyers. Charges col. E = réellement payées mais NON déductibles (incluses dans l'abattement forfaitaire). CFE et frais comptable inclus.

Sheet LMNP Réel
A1: LMNP RÉEL — DÉTAIL ANNUEL
A3: An | B3: Loyer brut | C3: Vacance | D3: Loyer net | E3: Charges déd. | F3: Intérêts | G3: Amort. total | H3: Bénéfice imp. | I3: Impôt | J3: Cash-flow | K3: Flux TRI | L3: Résultat avant report | M3: Stock déficit début | N3: Stock déficit fin
A4: 0 | K4: =-Paramètres!B10 -> -40000
A5: 1 | B5: =Paramètres!B27*12*(1+Paramètres!B28)^(1-1) -> 9600 | C5: =B5*Paramètres!B29 -> 800 | D5: =B5-C5 -> 8800 | E5: =(Paramètres!$B$32+Paramètres!$B$33+Paramètres!$B$34)*(1+Paramètres!$B$37)^(1-1)+Paramètres!$B$36*(1+Paramètres!$B$78)^(1-1)+Paramètres!$B$35*(1+Paramètres!$B$79)^(1-1) -> 2850 | F5: ='Amortissement crédit'!I4 -> 6233.5685 | G5: =IF(1<=Paramètres!B40,Paramètres!B43,0)+IF(1<=Paramètres!B41,Paramètres!B44,0)+IF(1<=Paramètres!B42,Paramètres!B45,0) -> 6797.619 | H5: =IF(L5<0,0,MAX(L5-M5,0)) -> 0 | I5: =H5*(Paramètres!D50+Paramètres!D51) -> 0 | J5: =D5-E5-I5-Paramètres!B24 -> -6646.7251 | K5: =J5+IF(1=Paramètres!B12,Paramètres!B18-'Amortissement crédit'!J4-'PV LMNP Réel'!B6,0) -> -6646.7251 | L5: =D5-E5-F5-G5 -> -7081.1875 | M5: =0 -> 0 | N5: =IF(L5<0,M5-L5,MAX(M5-L5,0)) -> 7081.1875
A6: 2 | B6: =Paramètres!B27*12*(1+Paramètres!B28)^(2-1) -> 9744 | C6: =B6*Paramètres!B29 -> 812 | D6: =B6-C6 -> 8932 | E6: =(Paramètres!$B$32+Paramètres!$B$33+Paramètres!$B$34)*(1+Paramètres!$B$37)^(2-1)+Paramètres!$B$36*(1+Paramètres!$B$78)^(2-1)+Paramètres!$B$35*(1+Paramètres!$B$79)^(2-1) -> 2907 | F6: ='Amortissement crédit'!I5 -> 6007.2504 | G6: =IF(2<=Paramètres!B40,Paramètres!B43,0)+IF(2<=Paramètres!B41,Paramètres!B44,0)+IF(2<=Paramètres!B42,Paramètres!B45,0) -> 6797.619 | H6: =IF(L6<0,0,MAX(L6-M6,0)) -> 0 | I6: =H6*(Paramètres!D50+Paramètres!D51) -> 0 | J6: =D6-E6-I6-Paramètres!B24 -> -6571.7251 | K6: =J6+IF(2=Paramètres!B12,Paramètres!B18-'Amortissement crédit'!J5-'PV LMNP Réel'!B6,0) -> -6571.7251 | L6: =D6-E6-F6-G6 -> -6779.8694 | M6: =N5 -> 7081.1875 | N6: =IF(L6<0,M6-L6,MAX(M6-L6,0)) -> 13861.057
A7: 3 | B7: =Paramètres!B27*12*(1+Paramètres!B28)^(3-1) -> 9890.16 | C7: =B7*Paramètres!B29 -> 824.18 | D7: =B7-C7 -> 9065.98 | E7: =(Paramètres!$B$32+Paramètres!$B$33+Paramètres!$B$34)*(1+Paramètres!$B$37)^(3-1)+Paramètres!$B$36*(1+Paramètres!$B$78)^(3-1)+Paramètres!$B$35*(1+Paramètres!$B$79)^(3-1) -> 2965.14 | F7: ='Amortissement crédit'!I6 -> 5772.8828 | G7: =IF(3<=Paramètres!B40,Paramètres!B43,0)+IF(3<=Paramètres!B41,Paramètres!B44,0)+IF(3<=Paramètres!B42,Paramètres!B45,0) -> 6797.619 | H7: =IF(L7<0,0,MAX(L7-M7,0)) -> 0 | I7: =H7*(Paramètres!D50+Paramètres!D51) -> 0 | J7: =D7-E7-I7-Paramètres!B24 -> -6495.8851 | K7: =J7+IF(3=Paramètres!B12,Paramètres!B18-'Amortissement crédit'!J6-'PV LMNP Réel'!B6,0) -> -6495.8851 | L7: =D7-E7-F7-G7 -> -6469.6619 | M7: =N6 -> 13861.057 | N7: =IF(L7<0,M7-L7,MAX(M7-L7,0)) -> 20330.719
A8: 4 | B8: =Paramètres!B27*12*(1+Paramètres!B28)^(4-1) -> 10038.512 | C8: =B8*Paramètres!B29 -> 836.5427 | D8: =B8-C8 -> 9201.9697 | E8: =(Paramètres!$B$32+Paramètres!$B$33+Paramètres!$B$34)*(1+Paramètres!$B$37)^(4-1)+Paramètres!$B$36*(1+Paramètres!$B$78)^(4-1)+Paramètres!$B$35*(1+Paramètres!$B$79)^(4-1) -> 3024.4428 | F8: ='Amortissement crédit'!I7 -> 5530.1796 | G8: =IF(4<=Paramètres!B40,Paramètres!B43,0)+IF(4<=Paramètres!B41,Paramètres!B44,0)+IF(4<=Paramètres!B42,Paramètres!B45,0) -> 6797.619 | H8: =IF(L8<0,0,MAX(L8-M8,0)) -> 0 | I8: =H8*(Paramètres!D50+Paramètres!D51) -> 0 | J8: =D8-E8-I8-Paramètres!B24 -> -6419.1982 | K8: =J8+IF(4=Paramètres!B12,Paramètres!B18-'Amortissement crédit'!J7-'PV LMNP Réel'!B6,0) -> -6419.1982 | L8: =D8-E8-F8-G8 -> -6150.2717 | M8: =N7 -> 20330.719 | N8: =IF(L8<0,M8-L8,MAX(M8-L8,0)) -> 26480.991
A9: 5 | B9: =Paramètres!B27*12*(1+Paramètres!B28)^(5-1) -> 10189.09 | C9: =B9*Paramètres!B29 -> 849.09084 | D9: =B9-C9 -> 9339.9992 | E9: =(Paramètres!$B$32+Paramètres!$B$33+Paramètres!$B$34)*(1+Paramètres!$B$37)^(5-1)+Paramètres!$B$36*(1+Paramètres!$B$78)^(5-1)+Paramètres!$B$35*(1+Paramètres!$B$79)^(5-1) -> 3084.9317 | F9: ='Amortissement crédit'!I8 -> 5278.8441 | G9: =IF(5<=Paramètres!B40,Paramètres!B43,0)+IF(5<=Paramètres!B41,Paramètres!B44,0)+IF(5<=Paramètres!B42,Paramètres!B45,0) -> 6797.619 | H9: =IF(L9<0,0,MAX(L9-M9,0)) -> 0 | I9: =H9*(Paramètres!D50+Paramètres!D51) -> 0 | J9: =D9-E9-I9-Paramètres!B24 -> -6341.6575 | K9: =J9+IF(5=Paramètres!B12,Paramètres!B18-'Amortissement crédit'!J8-'PV LMNP Réel'!B6,0) -> -6341.6575 | L9: =D9-E9-F9-G9 -> -5821.3955 | M9: =N8 -> 26480.991 | N9: =IF(L9<0,M9-L9,MAX(M9-L9,0)) -> 32302.386
A10: 6 | B10: =Paramètres!B27*12*(1+Paramètres!B28)^(6-1) -> 10341.926 | C10: =B10*Paramètres!B29 -> 861.8272 | D10: =B10-C10 -> 9480.0992 | E10: =(Paramètres!$B$32+Paramètres!$B$33+Paramètres!$B$34)*(1+Paramètres!$B$37)^(6-1)+Paramètres!$B$36*(1+Paramètres!$B$78)^(6-1)+Paramètres!$B$35*(1+Paramètres!$B$79)^(6-1) -> 3146.6303 | F10: ='Amortissement crédit'!I9 -> 5018.5693 | G10: =IF(6<=Paramètres!B40,Paramètres!B43,0)+IF(6<=Paramètres!B41,Paramètres!B44,0)+IF(6<=Paramètres!B42,Paramètres!B45,0) -> 6797.619 | H10: =IF(L10<0,0,MAX(L10-M10,0)) -> 0 | I10: =H10*(Paramètres!D50+Paramètres!D51) -> 0 | J10: =D10-E10-I10-Paramètres!B24 -> -6263.2561 | K10: =J10+IF(6=Paramètres!B12,Paramètres!B18-'Amortissement crédit'!J9-'PV LMNP Réel'!B6,0) -> -6263.2561 | L10: =D10-E10-F10-G10 -> -5482.7195 | M10: =N9 -> 32302.386 | N10: =IF(L10<0,M10-L10,MAX(M10-L10,0)) -> 37785.106
A11: 7 | B11: =Paramètres!B27*12*(1+Paramètres!B28)^(7-1) -> 10497.055 | C11: =B11*Paramètres!B29 -> 874.75461 | D11: =B11-C11 -> 9622.3007 | E11: =(Paramètres!$B$32+Paramètres!$B$33+Paramètres!$B$34)*(1+Paramètres!$B$37)^(7-1)+Paramètres!$B$36*(1+Paramètres!$B$78)^(7-1)+Paramètres!$B$35*(1+Paramètres!$B$79)^(7-1) -> 3209.5629 | F11: ='Amortissement crédit'!I10 -> 4749.0374 | G11: =IF(7<=Paramètres!B40,Paramètres!B43,0)+IF(7<=Paramètres!B41,Paramètres!B44,0)+IF(7<=Paramètres!B42,Paramètres!B45,0) -> 6797.619 | H11: =IF(L11<0,0,MAX(L11-M11,0)) -> 0 | I11: =H11*(Paramètres!D50+Paramètres!D51) -> 0 | J11: =D11-E11-I11-Paramètres!B24 -> -6183.9872 | K11: =J11+IF(7=Paramètres!B12,Paramètres!B18-'Amortissement crédit'!J10-'PV LMNP Réel'!B6,0) -> -6183.9872 | L11: =D11-E11-F11-G11 -> -5133.9187 | M11: =N10 -> 37785.106 | N11: =IF(L11<0,M11-L11,MAX(M11-L11,0)) -> 42919.024
A12: 8 | B12: =Paramètres!B27*12*(1+Paramètres!B28)^(8-1) -> 10654.511 | C12: =B12*Paramètres!B29 -> 887.87593 | D12: =B12-C12 -> 9766.6352 | E12: =(Paramètres!$B$32+Paramètres!$B$33+Paramètres!$B$34)*(1+Paramètres!$B$37)^(8-1)+Paramètres!$B$36*(1+Paramètres!$B$78)^(8-1)+Paramètres!$B$35*(1+Paramètres!$B$79)^(8-1) -> 3273.7542 | F12: ='Amortissement crédit'!I11 -> 4469.9191 | G12: =IF(8<=Paramètres!B40,Paramètres!B43,0)+IF(8<=Paramètres!B41,Paramètres!B44,0)+IF(8<=Paramètres!B42,Paramètres!B45,0) -> 6083.3333 | H12: =IF(L12<0,0,MAX(L12-M12,0)) -> 0 | I12: =H12*(Paramètres!D50+Paramètres!D51) -> 0 | J12: =D12-E12-I12-Paramètres!B24 -> -6103.844 | K12: =J12+IF(8=Paramètres!B12,Paramètres!B18-'Amortissement crédit'!J11-'PV LMNP Réel'!B6,0) -> -6103.844 | L12: =D12-E12-F12-G12 -> -4060.3714 | M12: =N11 -> 42919.024 | N12: =IF(L12<0,M12-L12,MAX(M12-L12,0)) -> 46979.396
A13: 9 | B13: =Paramètres!B27*12*(1+Paramètres!B28)^(9-1) -> 10814.329 | C13: =B13*Paramètres!B29 -> 901.19407 | D13: =B13-C13 -> 9913.1348 | E13: =(Paramètres!$B$32+Paramètres!$B$33+Paramètres!$B$34)*(1+Paramètres!$B$37)^(9-1)+Paramètres!$B$36*(1+Paramètres!$B$78)^(9-1)+Paramètres!$B$35*(1+Paramètres!$B$79)^(9-1) -> 3339.2292 | F13: ='Amortissement crédit'!I12 -> 4180.8734 | G13: =IF(9<=Paramètres!B40,Paramètres!B43,0)+IF(9<=Paramètres!B41,Paramètres!B44,0)+IF(9<=Paramètres!B42,Paramètres!B45,0) -> 6083.3333 | H13: =IF(L13<0,0,MAX(L13-M13,0)) -> 0 | I13: =H13*(Paramètres!D50+Paramètres!D51) -> 0 | J13: =D13-E13-I13-Paramètres!B24 -> -6022.8195 | K13: =J13+IF(9=Paramètres!B12,Paramètres!B18-'Amortissement crédit'!J12-'PV LMNP Réel'!B6,0) -> -6022.8195 | L13: =D13-E13-F13-G13 -> -3690.3012 | M13: =N12 -> 46979.396 | N13: =IF(L13<0,M13-L13,MAX(M13-L13,0)) -> 50669.697
A14: 10 | B14: =Paramètres!B27*12*(1+Paramètres!B28)^(10-1) -> 10976.544 | C14: =B14*Paramètres!B29 -> 914.71198 | D14: =B14-C14 -> 10061.832 | E14: =(Paramètres!$B$32+Paramètres!$B$33+Paramètres!$B$34)*(1+Paramètres!$B$37)^(10-1)+Paramètres!$B$36*(1+Paramètres!$B$78)^(10-1)+Paramètres!$B$35*(1+Paramètres!$B$79)^(10-1) -> 3406.0138 | F14: ='Amortissement crédit'!I13 -> 3881.5472 | G14: =IF(10<=Paramètres!B40,Paramètres!B43,0)+IF(10<=Paramètres!B41,Paramètres!B44,0)+IF(10<=Paramètres!B42,Paramètres!B45,0) -> 6083.3333 | H14: =IF(L14<0,0,MAX(L14-M14,0)) -> 0 | I14: =H14*(Paramètres!D50+Paramètres!D51) -> 0 | J14: =D14-E14-I14-Paramètres!B24 -> -5940.9071 | K14: =J14+IF(10=Paramètres!B12,Paramètres!B18-'Amortissement crédit'!J13-'PV LMNP Réel'!B6,0) -> -5940.9071 | L14: =D14-E14-F14-G14 -> -3309.0625 | M14: =N13 -> 50669.697 | N14: =IF(L14<0,M14-L14,MAX(M14-L14,0)) -> 53978.759
A15: 11 | B15: =Paramètres!B27*12*(1+Paramètres!B28)^(11-1) -> 11141.192 | C15: =B15*Paramètres!B29 -> 928.43266 | D15: =B15-C15 -> 10212.759 | E15: =(Paramètres!$B$32+Paramètres!$B$33+Paramètres!$B$34)*(1+Paramètres!$B$37)^(11-1)+Paramètres!$B$36*(1+Paramètres!$B$78)^(11-1)+Paramètres!$B$35*(1+Paramètres!$B$79)^(11-1) -> 3474.1341 | F15: ='Amortissement crédit'!I14 -> 3571.5749 | G15: =IF(11<=Paramètres!B40,Paramètres!B43,0)+IF(11<=Paramètres!B41,Paramètres!B44,0)+IF(11<=Paramètres!B42,Paramètres!B45,0) -> 6083.3333 | H15: =IF(L15<0,0,MAX(L15-M15,0)) -> 0 | I15: =H15*(Paramètres!D50+Paramètres!D51) -> 0 | J15: =D15-E15-I15-Paramètres!B24 -> -5858.0999 | K15: =J15+IF(11=Paramètres!B12,Paramètres!B18-'Amortissement crédit'!J14-'PV LMNP Réel'!B6,0) -> -5858.0999 | L15: =D15-E15-F15-G15 -> -2916.283 | M15: =N14 -> 53978.759 | N15: =IF(L15<0,M15-L15,MAX(M15-L15,0)) -> 56895.042
A16: 12 | B16: =Paramètres!B27*12*(1+Paramètres!B28)^(12-1) -> 11308.31 | C16: =B16*Paramètres!B29 -> 942.35915 | D16: =B16-C16 -> 10365.951 | E16: =(Paramètres!$B$32+Paramètres!$B$33+Paramètres!$B$34)*(1+Paramètres!$B$37)^(12-1)+Paramètres!$B$36*(1+Paramètres!$B$78)^(12-1)+Paramètres!$B$35*(1+Paramètres!$B$79)^(12-1) -> 3543.6168 | F16: ='Amortissement crédit'!I15 -> 3250.5778 | G16: =IF(12<=Paramètres!B40,Paramètres!B43,0)+IF(12<=Paramètres!B41,Paramètres!B44,0)+IF(12<=Paramètres!B42,Paramètres!B45,0) -> 6083.3333 | H16: =IF(L16<0,0,MAX(L16-M16,0)) -> 0 | I16: =H16*(Paramètres!D50+Paramètres!D51) -> 0 | J16: =D16-E16-I16-Paramètres!B24 -> -5774.3912 | K16: =J16+IF(12=Paramètres!B12,Paramètres!B18-'Amortissement crédit'!J15-'PV LMNP Réel'!B6,0) -> -5774.3912 | L16: =D16-E16-F16-G16 -> -2511.5772 | M16: =N15 -> 56895.042 | N16: =IF(L16<0,M16-L16,MAX(M16-L16,0)) -> 59406.62
A17: 13 | B17: =Paramètres!B27*12*(1+Paramètres!B28)^(13-1) -> 11477.934 | C17: =B17*Paramètres!B29 -> 956.49454 | D17: =B17-C17 -> 10521.44 | E17: =(Paramètres!$B$32+Paramètres!$B$33+Paramètres!$B$34)*(1+Paramètres!$B$37)^(13-1)+Paramètres!$B$36*(1+Paramètres!$B$78)^(13-1)+Paramètres!$B$35*(1+Paramètres!$B$79)^(13-1) -> 3614.4891 | F17: ='Amortissement crédit'!I16 -> 2918.1638 | G17: =IF(13<=Paramètres!B40,Paramètres!B43,0)+IF(13<=Paramètres!B41,Paramètres!B44,0)+IF(13<=Paramètres!B42,Paramètres!B45,0) -> 5666.6667 | H17: =IF(L17<0,0,MAX(L17-M17,0)) -> 0 | I17: =H17*(Paramètres!D50+Paramètres!D51) -> 0 | J17: =D17-E17-I17-Paramètres!B24 -> -5689.7743 | K17: =J17+IF(13=Paramètres!B12,Paramètres!B18-'Amortissement crédit'!J16-'PV LMNP Réel'!B6,0) -> -5689.7743 | L17: =D17-E17-F17-G17 -> -1677.8797 | M17: =N16 -> 59406.62 | N17: =IF(L17<0,M17-L17,MAX(M17-L17,0)) -> 61084.499
A18: 14 | B18: =Paramètres!B27*12*(1+Paramètres!B28)^(14-1) -> 11650.103 | C18: =B18*Paramètres!B29 -> 970.84196 | D18: =B18-C18 -> 10679.262 | E18: =(Paramètres!$B$32+Paramètres!$B$33+Paramètres!$B$34)*(1+Paramètres!$B$37)^(14-1)+Paramètres!$B$36*(1+Paramètres!$B$78)^(14-1)+Paramètres!$B$35*(1+Paramètres!$B$79)^(14-1) -> 3686.7789 | F18: ='Amortissement crédit'!I17 -> 2573.9268 | G18: =IF(14<=Paramètres!B40,Paramètres!B43,0)+IF(14<=Paramètres!B41,Paramètres!B44,0)+IF(14<=Paramètres!B42,Paramètres!B45,0) -> 5666.6667 | H18: =IF(L18<0,0,MAX(L18-M18,0)) -> 0 | I18: =H18*(Paramètres!D50+Paramètres!D51) -> 0 | J18: =D18-E18-I18-Paramètres!B24 -> -5604.2425 | K18: =J18+IF(14=Paramètres!B12,Paramètres!B18-'Amortissement crédit'!J17-'PV LMNP Réel'!B6,0) -> -5604.2425 | L18: =D18-E18-F18-G18 -> -1248.1109 | M18: =N17 -> 61084.499 | N18: =IF(L18<0,M18-L18,MAX(M18-L18,0)) -> 62332.61
A19: 15 | B19: =Paramètres!B27*12*(1+Paramètres!B28)^(15-1) -> 11824.855 | C19: =B19*Paramètres!B29 -> 985.40458 | D19: =B19-C19 -> 10839.45 | E19: =(Paramètres!$B$32+Paramètres!$B$33+Paramètres!$B$34)*(1+Paramètres!$B$37)^(15-1)+Paramètres!$B$36*(1+Paramètres!$B$78)^(15-1)+Paramètres!$B$35*(1+Paramètres!$B$79)^(15-1) -> 3760.5145 | F19: ='Amortissement crédit'!I18 -> 2217.4465 | G19: =IF(15<=Paramètres!B40,Paramètres!B43,0)+IF(15<=Paramètres!B41,Paramètres!B44,0)+IF(15<=Paramètres!B42,Paramètres!B45,0) -> 5666.6667 | H19: =IF(L19<0,0,MAX(L19-M19,0)) -> 0 | I19: =H19*(Paramètres!D50+Paramètres!D51) -> 0 | J19: =D19-E19-I19-Paramètres!B24 -> -5517.7891 | K19: =J19+IF(15=Paramètres!B12,Paramètres!B18-'Amortissement crédit'!J18-'PV LMNP Réel'!B6,0) -> 172147.05 | L19: =D19-E19-F19-G19 -> -805.17716 | M19: =N18 -> 62332.61 | N19: =IF(L19<0,M19-L19,MAX(M19-L19,0)) -> 63137.787
A20: 16 | B20: =Paramètres!B27*12*(1+Paramètres!B28)^(16-1) -> 12002.228 | C20: =B20*Paramètres!B29 -> 1000.1857 | D20: =B20-C20 -> 11002.042 | E20: =(Paramètres!$B$32+Paramètres!$B$33+Paramètres!$B$34)*(1+Paramètres!$B$37)^(16-1)+Paramètres!$B$36*(1+Paramètres!$B$78)^(16-1)+Paramètres!$B$35*(1+Paramètres!$B$79)^(16-1) -> 3835.7248 | F20: ='Amortissement crédit'!I19 -> 1848.2871 | G20: =IF(16<=Paramètres!B40,Paramètres!B43,0)+IF(16<=Paramètres!B41,Paramètres!B44,0)+IF(16<=Paramètres!B42,Paramètres!B45,0) -> 5666.6667 | H20: =IF(L20<0,0,MAX(L20-M20,0)) -> 0 | I20: =H20*(Paramètres!D50+Paramètres!D51) -> 0 | J20: =D20-E20-I20-Paramètres!B24 -> -5430.4077 | K20: =J20+IF(16=Paramètres!B12,Paramètres!B18-'Amortissement crédit'!J19-'PV LMNP Réel'!B6,0) -> -5430.4077 | L20: =D20-E20-F20-G20 -> -348.63638 | M20: =N19 -> 63137.787 | N20: =IF(L20<0,M20-L20,MAX(M20-L20,0)) -> 63486.424
A21: 17 | B21: =Paramètres!B27*12*(1+Paramètres!B28)^(17-1) -> 12182.261 | C21: =B21*Paramètres!B29 -> 1015.1884 | D21: =B21-C21 -> 11167.073 | E21: =(Paramètres!$B$32+Paramètres!$B$33+Paramètres!$B$34)*(1+Paramètres!$B$37)^(17-1)+Paramètres!$B$36*(1+Paramètres!$B$78)^(17-1)+Paramètres!$B$35*(1+Paramètres!$B$79)^(17-1) -> 3912.4393 | F21: ='Amortissement crédit'!I20 -> 1465.998 | G21: =IF(17<=Paramètres!B40,Paramètres!B43,0)+IF(17<=Paramètres!B41,Paramètres!B44,0)+IF(17<=Paramètres!B42,Paramètres!B45,0) -> 5666.6667 | H21: =IF(L21<0,0,MAX(L21-M21,0)) -> 0 | I21: =H21*(Paramètres!D50+Paramètres!D51) -> 0 | J21: =D21-E21-I21-Paramètres!B24 -> -5342.0915 | K21: =J21+IF(17=Paramètres!B12,Paramètres!B18-'Amortissement crédit'!J20-'PV LMNP Réel'!B6,0) -> -5342.0915 | L21: =D21-E21-F21-G21 -> 121.96894 | M21: =N20 -> 63486.424 | N21: =IF(L21<0,M21-L21,MAX(M21-L21,0)) -> 63364.455
A22: 18 | B22: =Paramètres!B27*12*(1+Paramètres!B28)^(18-1) -> 12364.995 | C22: =B22*Paramètres!B29 -> 1030.4163 | D22: =B22-C22 -> 11334.579 | E22: =(Paramètres!$B$32+Paramètres!$B$33+Paramètres!$B$34)*(1+Paramètres!$B$37)^(18-1)+Paramètres!$B$36*(1+Paramètres!$B$78)^(18-1)+Paramètres!$B$35*(1+Paramètres!$B$79)^(18-1) -> 3990.688 | F22: ='Amortissement crédit'!I21 -> 1070.1119 | G22: =IF(18<=Paramètres!B40,Paramètres!B43,0)+IF(18<=Paramètres!B41,Paramètres!B44,0)+IF(18<=Paramètres!B42,Paramètres!B45,0) -> 5666.6667 | H22: =IF(L22<0,0,MAX(L22-M22,0)) -> 0 | I22: =H22*(Paramètres!D50+Paramètres!D51) -> 0 | J22: =D22-E22-I22-Paramètres!B24 -> -5252.8342 | K22: =J22+IF(18=Paramètres!B12,Paramètres!B18-'Amortissement crédit'!J21-'PV LMNP Réel'!B6,0) -> -5252.8342 | L22: =D22-E22-F22-G22 -> 607.1123 | M22: =N21 -> 63364.455 | N22: =IF(L22<0,M22-L22,MAX(M22-L22,0)) -> 62757.342
A23: 19 | B23: =Paramètres!B27*12*(1+Paramètres!B28)^(19-1) -> 12550.47 | C23: =B23*Paramètres!B29 -> 1045.8725 | D23: =B23-C23 -> 11504.598 | E23: =(Paramètres!$B$32+Paramètres!$B$33+Paramètres!$B$34)*(1+Paramètres!$B$37)^(19-1)+Paramètres!$B$36*(1+Paramètres!$B$78)^(19-1)+Paramètres!$B$35*(1+Paramètres!$B$79)^(19-1) -> 4070.5018 | F23: ='Amortissement crédit'!I22 -> 660.14539 | G23: =IF(19<=Paramètres!B40,Paramètres!B43,0)+IF(19<=Paramètres!B41,Paramètres!B44,0)+IF(19<=Paramètres!B42,Paramètres!B45,0) -> 5666.6667 | H23: =IF(L23<0,0,MAX(L23-M23,0)) -> 0 | I23: =H23*(Paramètres!D50+Paramètres!D51) -> 0 | J23: =D23-E23-I23-Paramètres!B24 -> -5162.6293 | K23: =J23+IF(19=Paramètres!B12,Paramètres!B18-'Amortissement crédit'!J22-'PV LMNP Réel'!B6,0) -> -5162.6293 | L23: =D23-E23-F23-G23 -> 1107.2837 | M23: =N22 -> 62757.342 | N23: =IF(L23<0,M23-L23,MAX(M23-L23,0)) -> 61650.059
A24: 20 | B24: =Paramètres!B27*12*(1+Paramètres!B28)^(20-1) -> 12738.727 | C24: =B24*Paramètres!B29 -> 1061.5606 | D24: =B24-C24 -> 11677.167 | E24: =(Paramètres!$B$32+Paramètres!$B$33+Paramètres!$B$34)*(1+Paramètres!$B$37)^(20-1)+Paramètres!$B$36*(1+Paramètres!$B$78)^(20-1)+Paramètres!$B$35*(1+Paramètres!$B$79)^(20-1) -> 4151.9118 | F24: ='Amortissement crédit'!I23 -> 235.59763 | G24: =IF(20<=Paramètres!B40,Paramètres!B43,0)+IF(20<=Paramètres!B41,Paramètres!B44,0)+IF(20<=Paramètres!B42,Paramètres!B45,0) -> 5666.6667 | H24: =IF(L24<0,0,MAX(L24-M24,0)) -> 0 | I24: =H24*(Paramètres!D50+Paramètres!D51) -> 0 | J24: =D24-E24-I24-Paramètres!B24 -> -5071.4704 | K24: =J24+IF(20=Paramètres!B12,Paramètres!B18-'Amortissement crédit'!J23-'PV LMNP Réel'!B6,0) -> -5071.4704 | L24: =D24-E24-F24-G24 -> 1622.9904 | M24: =N23 -> 61650.059 | N24: =IF(L24<0,M24-L24,MAX(M24-L24,0)) -> 60027.068
A26: RÉSUMÉ & RENDEMENTS
A27: Cash-flow cumulé hors revente (mise comprise) (€) | K27: =-Paramètres!B10+SUMPRODUCT((J5:J24)*(ROW(J5:J24)-4<=Paramètres!B12*1)) -> -131434.3
